<?xml version="1.0" ?>
  <robot name="moba">

<link name="world"></link>

  <link name="chassis">
    <visual>
      <geometry>
          <box size=".8 0.7 0.2"/>
      </geometry>
      <material name="red">
        <color rgba=".8 .2 .1 1" />
      </material>
    </visual>
  <inertial>
            <mass value="2" />
            <inertia ixx="0.088333333" ixy="0.0" ixz="0" 
            iyy="0.113333333" iyz="0" izz="0.113333333" />
    </inertial>
    
    <collision>
      <geometry>
          <box size=".8 0.7 0.2"/>
      </geometry>
    </collision>
  </link>

  <link name="wheel_front_right">
    <inertial>
            <mass value="1.5" />
            <inertia ixx="0.0096875" ixy="0.0" ixz="0" 
            iyy="0.0096875" iyz="0" izz="0.016875" />
    </inertial>

    <visual>
      
      <geometry>
          <cylinder radius="0.15" length="0.1"/>
      </geometry>
      <material name="black">
        <color rgba="0.45 0.45 0.45 1"/>
      </material>
    </visual>

    <collision>
    
      <geometry>
          <cylinder radius="0.15" length="0.1"/>
      </geometry>
      <contact_coefficients mu="1" kp="1e+13" kd="1.0"/>
    </collision>
  </link>

  <joint name="wheel_front_right_joint" type="continuous">
    <origin xyz="0.25 0.4 -0.1" rpy="1.57 0.0 0.0"/>
    <parent link="chassis"/>
    <child link="wheel_front_right"/>
    <axis xyz="0.0 0.0 1.0"/>
  </joint>

  <link name="wheel_front_left">
    <inertial>
            <mass value="1.5" />
            <inertia ixx="0.0096875" ixy="0.0" ixz="0" 
            iyy="0.0096875" iyz="0" izz="0.016875" />
    </inertial>

    <visual>
      
      <geometry>
          <cylinder radius="0.15" length="0.1"/>
      </geometry>
      <material name="black">
        <color rgba="0.45 0.45 0.45 1"/>
      </material>
    </visual>

    <collision>
      <geometry>
          <cylinder radius="0.15" length="0.1"/>
      </geometry>
      <contact_coefficients mu="1" kp="1e+13" kd="1.0"/>
    </collision>
  </link>

  <joint name="wheel_front_left_joint" type="continuous">
    <origin xyz="0.25 -0.4 -0.1" rpy="1.57 0.0 0.0"/>
    <parent link="chassis"/>
    <child link="wheel_front_left"/>
    <axis xyz="0.0 0.0 1.0"/>

  </joint>

<link name="wheel_back_right">
    <inertial>
            <mass value="1.5" />
            <inertia ixx="0.0096875" ixy="0.0" ixz="0" 
            iyy="0.0096875" iyz="0" izz="0.016875" />
    </inertial>

    <visual>
      
      <geometry>
          <cylinder radius="0.15" length="0.1"/>
      </geometry>
      <material name="black">
        <color rgba="0.45 0.45 0.45 1"/>
      </material>
    </visual>

    <collision>
      <geometry>
          <cylinder radius="0.15" length="0.1"/>
      </geometry>
      <contact_coefficients mu="1" kp="1e+13" kd="1.0"/>
    </collision>
  </link>

  <joint name="wheel_back_right_joint" type="continuous">
    <origin xyz="-0.25 0.4 -0.1" rpy="1.57 0.0 0.0"/>
    <parent link="chassis"/>
    <child link="wheel_back_right"/>
    <axis xyz="0.0 0.0 1.0"/>

  </joint>

  <link name="wheel_back_left">
    <inertial>
            <mass value="1.5" />
            <inertia ixx="0.0096875" ixy="0.0" ixz="0" 
            iyy="0.0096875" iyz="0" izz="0.016875" />
    </inertial>

    <visual>
      
      <geometry>
          <cylinder radius="0.15" length="0.1"/>
      </geometry>
      <material name="black">
        <color rgba="0.45 0.45 0.45 1"/>
      </material>
    </visual>

    <collision>
      <geometry>
          <cylinder radius="0.15" length="0.1"/>
      </geometry>
      <contact_coefficients mu="1" kp="1e+13" kd="1.0"/>
    </collision>
  </link>

  <joint name="wheel_back_left_joint" type="continuous">
    <origin xyz="-0.25 -0.4 -0.1" rpy="1.57 0.0 0.0"/>
    <parent link="chassis"/>
    <child link="wheel_back_left"/>
    <axis xyz="0.0 0.0 1.0"/>

  </joint>

  <link name="camera">
    <inertial>
            <mass value="0.3" />
            <inertia ixx="0.00057" ixy="0.0" ixz="0" 
            iyy="0.00057" iyz="0" izz="0.00096" />
    </inertial>

    <visual>
      
      <geometry>
        <cylinder radius="0.08" length="0.06"/>
      </geometry>
      <material name="blue">
        <color rgba="0 0.8 0.8 1"/>
      </material>
    </visual>

    <collision>
      <geometry>
          <cylinder radius="0.08" length="0.06"/>
      </geometry>
    </collision>
  </link>

  <joint name="camera_joint" type="fixed">
    <origin xyz="-0.4 0 0.0" rpy="0.0 1.57 0.0"/>
    <parent link="chassis"/>
    <child link="camera"/>
    <axis xyz="0.0 0.0 1.0"/>

  </joint>

  <link name="lidar">
    <inertial>
            <mass value="0.5" />
            <inertia ixx="0.002219792" ixy="0.0" ixz="0" 
            iyy="0.002219792" iyz="0" izz="0.00390625" />
    </inertial>

    <visual>
      <geometry>
        <cylinder radius="0.125" length="0.08"/>
      </geometry>
      <material name="yellow">
        <color rgba="1 1 0 1"/>
      </material>
    </visual>

    <collision>
      <geometry>
        <cylinder radius="0.125" length="0.08"/>
      </geometry>
    </collision>
  </link>

  <joint name="lidar_joint" type="fixed">
    <origin xyz="-0.25 0 0.14" rpy="0 0.0 1.57"/>
    <parent link="chassis"/>
    <child link="lidar"/>
    <axis xyz="0.0 0.0 1.0"/>

  </joint>

 


<!-- GAZEBO COLOUR-->

  <gazebo reference="chassis">
    <material>Gazebo/Red</material>
  </gazebo>
  <gazebo reference="fork">
    <material>Gazebo/Gray</material>
  </gazebo>
  <gazebo reference="lidar">
   <material>Gazebo/Yellow</material>
  </gazebo> 
  <gazebo reference="wheel_front_right">
    <material>Gazebo/Gray</material>
  </gazebo>
  <gazebo reference="wheel_front_left">
    <material>Gazebo/Gray</material>
  </gazebo> 
  <gazebo reference="wheel_back_right">
    <material>Gazebo/Gray</material>
  </gazebo>
  <gazebo reference="wheel_back_left">
    <material>Gazebo/Gray</material>
  </gazebo> 


<!-- DIFFENERNTIAL DRIVE-->

  <gazebo>
<plugin name='diff_drive' filename='libgazebo_ros_diff_drive.so'>
        <left_joint>wheel_front_left_joint</left_joint>
        <right_joint>wheel_front_right_joint</right_joint>
        <wheel_separation>0.8</wheel_separation>
        <wheel_diameter>0.3</wheel_diameter>
        <max_wheel_torque>20</max_wheel_torque>
        <max_wheel_acceleration>1.0</max_wheel_acceleration>]
        <publish_odom>true</publish_odom>
        <publish_odom_tf>true</publish_odom_tf>
        <publish_wheel_tf>true</publish_wheel_tf>
        <commandTopic>cmd_vel</commandTopic>
        <odometryTopic>odom</odometryTopic>
        <odometryFrame>world</odometryFrame>
        <robotBaseFrame>chassis</robotBaseFrame>

      </plugin>
</gazebo>

<gazebo>
    <plugin name='diff_drive' filename='libgazebo_ros_diff_drive.so'>
            <left_joint>wheel_back_left_joint</left_joint>
            <right_joint>wheel_back_right_joint</right_joint>
            <wheel_separation>0.8</wheel_separation>
            <wheel_diameter>0.3</wheel_diameter>
            <max_wheel_torque>20</max_wheel_torque>
            <max_wheel_acceleration>1.0</max_wheel_acceleration>]
    
          </plugin>
    </gazebo>

  
    <gazebo>
      <plugin name="gazebo_ros_joint_state_publisher"
          filename="libgazebo_ros_joint_state_publisher.so">
          <update_rate>20</update_rate>
          <joint_name>fork_joint</joint_name>
      </plugin>
    </gazebo>

    <gazebo>
      <plugin name="gazebo_ros_joint_pose_trajectory"
          filename="libgazebo_ros_joint_pose_trajectory.so">
          <update_rate>2</update_rate>
      </plugin>
    </gazebo>




<!-- CAMERA-->
      <gazebo reference="camera">
    <sensor type="camera" name="camera1">
      <update_rate>30.0</update_rate>
      <camera name="head">
        <horizontal_fov>1.3962634</horizontal_fov>
        <image>
          <width>800</width>
          <height>800</height>
          <format>R8G8B8</format>
        </image>
        <clip>
          <near>0.02</near>
          <far>300</far>
        </clip>
        <noise>
          <type>gaussian</type>
          <mean>0.0</mean>
          <stddev>0.007</stddev>
        </noise>
      </camera>
      <plugin name="camera_controller" filename="libgazebo_ros_camera.so">
        <alwaysOn>true</alwaysOn>
        <updateRate>0.0</updateRate>
        <cameraName>/camera</cameraName>
        <imageTopicName>image_raw</imageTopicName>
        <cameraInfoTopicName>camera_info</cameraInfoTopicName>
        <frameName>camera_link</frameName>
        <hackBaseline>0.07</hackBaseline>
      </plugin>
    </sensor>
    <material>Gazebo/Blue</material>
  </gazebo>

<!-- LIDAR-->
   <gazebo reference="lidar">
    <sensor name="gazebo_lidar" type="ray">
      <visualize>true</visualize>
      <update_rate>12.0</update_rate>
      <plugin filename="libgazebo_ros_ray_sensor.so" name="gazebo_lidar">
      <ros>
        <remapping>~/out:=scan</remapping>
      </ros>
      
      <output_type>sensor_msgs/LaserScan</output_type>
      <frame_name>lidar</frame_name>
      </plugin>
      <ray>
        <scan>
          <horizontal>
            <samples>360</samples>
            <resolution>1</resolution>
            <min_angle>0.00</min_angle>
            <max_angle>3.14</max_angle>
          </horizontal>
        </scan>
        <range>
          <min>0.120</min>
          <max>3.5</max>
          <resolution>0.015</resolution>
        </range>
        <noise>
          <type>gaussian</type>
          <mean>0.0</mean>
          <stddev>0.01</stddev>
        </noise>
      </ray>
    </sensor>
  </gazebo> 

</robot>